Traceback (most recent call last):
  File "/opt/hostedtoolcache/Python/3.9.18/x64/lib/python3.9/site-packages/jupyter_cache/executors/utils.py", line 58, in single_nb_execution
    executenb(
  File "/opt/hostedtoolcache/Python/3.9.18/x64/lib/python3.9/site-packages/nbclient/client.py", line 1305, in execute
    return NotebookClient(nb=nb, resources=resources, km=km, **kwargs).execute()
  File "/opt/hostedtoolcache/Python/3.9.18/x64/lib/python3.9/site-packages/jupyter_core/utils/__init__.py", line 162, in wrapped
    return loop.run_until_complete(inner)
  File "/opt/hostedtoolcache/Python/3.9.18/x64/lib/python3.9/asyncio/base_events.py", line 647, in run_until_complete
    return future.result()
  File "/opt/hostedtoolcache/Python/3.9.18/x64/lib/python3.9/site-packages/nbclient/client.py", line 705, in async_execute
    await self.async_execute_cell(
  File "/opt/hostedtoolcache/Python/3.9.18/x64/lib/python3.9/site-packages/nbclient/client.py", line 1058, in async_execute_cell
    await self._check_raise_for_error(cell, cell_index, exec_reply)
  File "/opt/hostedtoolcache/Python/3.9.18/x64/lib/python3.9/site-packages/nbclient/client.py", line 914, in _check_raise_for_error
    raise CellExecutionError.from_cell_and_msg(cell, exec_reply_content)
nbclient.exceptions.CellExecutionError: An error occurred while executing the following cell:
------------------
import timeit

def time_second_order():
    return exptaylor(1, 2)

def time_tenth_order():
    return exptaylor(1, 10)

# timing the functions
time_second_order_duration = timeit.timeit(time_second_order, number=1000)
time_tenth_order_duration = timeit.timeit(time_tenth_order, number=1000)

# calculate the average time per run for both cases
average_time_second_order = time_second_order_duration / 1000
average_time_tenth_order = time_tenth_order_duration / 1000

# estimate the time for a 100,000-order series
# this is a simple estimate, real performance may vary due to computational complexity
estimate_100k_order = (average_time_tenth_order / 10) * 100000

print(estimate_100k_orde)
------------------


[0;31m---------------------------------------------------------------------------[0m
[0;31mNameError[0m                                 Traceback (most recent call last)
Cell [0;32mIn[16], line 21[0m
[1;32m     17[0m [38;5;66;03m# estimate the time for a 100,000-order series[39;00m
[1;32m     18[0m [38;5;66;03m# this is a simple estimate, real performance may vary due to computational complexity[39;00m
[1;32m     19[0m estimate_100k_order [38;5;241m=[39m (average_time_tenth_order [38;5;241m/[39m [38;5;241m10[39m) [38;5;241m*[39m [38;5;241m100000[39m
[0;32m---> 21[0m [38;5;28mprint[39m([43mestimate_100k_orde[49m)

[0;31mNameError[0m: name 'estimate_100k_orde' is not defined

